<?xml version="1.0"?>
<robot name="my_rb1_robot">
  <material name="blue">
    <color rgba="0 0 0.8 1.0"/>
  </material>
  <material name="red">
    <color rgba="0.8 0 0 1.0" />
  </material>
  <material name="black">
    <color rgba="0 0 0 1.0"/>
  </material>
  <material name="white">
    <color rgba="1 1 1 1.0"/>
  </material>

  <!-- Basic Link-->
  <link name="base_link">
    <visual>
      <origin rpy="0 0 0" xyz="0 0 0"/>
      <geometry>
        <cylinder radius="0.25" length="0.3"/>
      </geometry>
      <material name="blue"/>
    </visual>
    <collision>
      <origin rpy="0 0 0" xyz="0 0 0"/>
      <geometry>
        <cylinder radius="0.25" length="0.3"/>
      </geometry>
    </collision>
    <inertial>
      <mass value="20.0"/>
      <origin rpy="0 0 0" xyz="0 0 0"/>
      <inertia ixx="0.9375" ixy="0.0" ixz="0.0" iyy="0.9375" iyz="0.0" izz="0.625"/>
    </inertial>
  </link>
  <gazebo reference="base_link">
    <material>Gazebo/Blue</material>
  </gazebo>

  <!-- Link for base_footprint-->
  <link name="base_footprint">
    <inertial>
      <mass value="0.0001"/>
      <origin xyz="0 0 0"/>
      <inertia ixx="0.0001" ixy="0.0" ixz="0.0" iyy="0.0001" iyz="0.0" izz="0.0001"/>
    </inertial>
    <visual>
      <origin rpy="0 0 0" xyz="0 0 0"/>
      <geometry>
        <cylinder radius="0.001" length="0.001"/>
      </geometry>
    </visual>
  \   </link>
  <gazebo reference="base_footprint">
  <material>Gazebo/White</material>
  </gazebo>

  <!-- Joint for base_footprint-->
  <joint name="base_footprint_joint" type="fixed">
  <parent link="base_footprint"/>
  <child link="base_link"/>
  <origin rpy="0 0 0" xyz="0.0 0.0 0.12"/>
  </joint>


  <!--Link for left_wheel-->
  <link name="left_wheel">
    <visual>
      <geometry>
        <cylinder radius="0.05" length="0.06"/>
      </geometry>
      <origin rpy="1.57075 0 0" xyz="0 0 0"/>
      <material name="red" />
    </visual>
    <collision>
      <origin rpy="1.57075 0 0" xyz="0 0 0"/>
      <geometry>
        <cylinder radius="0.05" length="0.06"/>
      </geometry>
    </collision>
    <inertial>
      <mass value="2.0"/>
      <origin rpy="1.57075 0 0" xyz="0 0 0"/>
      <inertia ixx="0.00185" ixy="0.0" ixz="0.0" iyy="0.00185" iyz="0.0" izz="0.0025"/>
    </inertial>
  </link>
  <gazebo reference="left_wheel">
    <material>Gazebo/Red</material>
  </gazebo>

  <!-- Joint for left_wheel-->
  <joint name="joint_left_wheel" type="continuous">
    <parent link="base_link"/>
    <child link="left_wheel"/>
    <origin xyz="0.0 0.225 -0.125" rpy="0.0 0.0 0.0"/>
    <axis rpy="0 0 0" xyz="0 1 0" />
    <limit effort="10000" velocity="1000" />
    <joint_properties damping="1.0" friction="1.0" />
  </joint>

   <!-- Transmission is important to link the joints and the controller -->
   <transmission name="joint_left_wheel_trans">
    <type>transmission_interface/SimpleTransmission</type>
    <joint name="joint_left_wheel"/>
    <actuator name="joint_left_wheel_motor">
      <hardwareInterface>EffortJointInterface</hardwareInterface>
      <mechanicalReduction>1</mechanicalReduction>
    </actuator>
  </transmission>

  <!-- Link for right_wheel -->
  <link name="right_wheel">
    <visual>
      <geometry>
        <cylinder radius="0.05" length="0.06"/>
      </geometry>
      <origin rpy="1.57075 0 0" xyz="0 0 0"/>
      <material name="red" />
    </visual>
    <collision>
      <geometry>
        <cylinder radius="0.05" length="0.06"/>
      </geometry>
      <origin rpy="1.57075 0 0" xyz="0 0 0"/>
    </collision>
    <inertial>
      <mass value="2.0"/>
      <origin rpy="1.57075 0 0" xyz="0 0 0"/>
      <inertia ixx="0.00185" ixy="0.0" ixz="0.0" iyy="0.00185" iyz="0.0" izz="0.0025"/>
    </inertial>
  </link>
  <gazebo reference="right_wheel">
    <material>Gazebo/Red</material>
  </gazebo>

  <!-- Joint for Right_wheel-->
  <joint name="joint_right_wheel" type="continuous">
    <parent link="base_link"/>
    <child link="right_wheel"/>
    <origin xyz="0.0 -0.225 -0.125" rpy="0.0 0.0 0.0"/>
    <axis rpy="0 0 0" xyz="0 1 0" />
    <limit effort="10000" velocity="1000" />
    <joint_properties damping="1.0" friction="1.0" />
  </joint>

  <!-- Transmission is important to link the joints and the controller -->
  <transmission name="joint_right_wheel_trans">
    <type>transmission_interface/SimpleTransmission</type>
    <joint name="joint_right_wheel"/>
    <actuator name="joint_right_wheel_motor">
      <hardwareInterface>EffortJointInterface</hardwareInterface>
      <mechanicalReduction>1</mechanicalReduction>
    </actuator>
  </transmission>

  <!-- Link for front_caster-->
  <link name="front_caster">
    <visual>
      <geometry>
        <sphere radius="0.025"/>
      </geometry>
      <material name="black" />
    </visual>
    <collision>
      <geometry>
        <sphere radius="0.025"/>
      </geometry>
    </collision>
    <inertial>
      <mass value="0.5"/>
      <inertia ixx="0.000125" ixy="0.0" ixz="0.0" iyy="0.000125" iyz="0.0" izz="0.000125"/>
    </inertial>
  </link>
  <gazebo reference="front_caster">
    <material>Gazebo/Black</material>
  </gazebo>

  <!-- Joint for front_caster -->
  <joint name="joint_front_caster" type="continuous">
    <parent link="base_link"/>
    <child link="front_caster"/>
    <origin xyz="0.15 0.0 -0.15" rpy="0.0 0.0 0.0"/>
    <axis xyz="1.0 1.0 0.0"/>
    <limit lower="0.0" upper="0.0" effort="0.0" velocity="0.0"/>
  </joint>

  <!-- Link for back_caster -->
  <link name="back_caster">
    <visual>
      <geometry>
        <sphere radius="0.025"/>
      </geometry>
      <material name="black" />
    </visual>
    <collision>
      <geometry>
        <sphere radius="0.025"/>
      </geometry>
    </collision>
    <inertial>
      <mass value="0.5"/>
      <inertia ixx="0.000125" ixy="0.0" ixz="0.0" iyy="0.000125" iyz="0.0" izz="0.000125"/>
    </inertial>
  </link>
  <gazebo reference="back_caster">
    <material>Gazebo/Black</material>
  </gazebo>

  <!-- Joint for back_caster -->
  <joint name="joint_back_caster" type="continuous">
    <parent link="base_link"/>
    <child link="back_caster"/>
    <origin xyz="-0.15 0.0 -0.15" rpy="0.0 0.0 0.0"/>
    <axis xyz="1.0 1.0 0.0"/>
    <limit lower="0.0" upper="0.0" effort="0.0" velocity="0.0"/>
  </joint>

  <!-- Link for front_laser -->
  <link name="front_laser">
    <visual>
      <geometry>
        <sphere radius="0.02"/>
      </geometry>
      <material name="black"/>
    </visual>
    <collision>
      <geometry>
        <sphere radius="0.02"/>
      </geometry>
    </collision>
    <inertial>
      <mass value="0.01"/>
      <inertia ixx="0.00001" ixy="0.0" ixz="0.0" iyy="0.00001" iyz="0.0" izz="0.00001"/>
    </inertial>
  </link>
  <gazebo reference="front_laser">
    <material>Gazebo/Grey</material>
  </gazebo>

  <!-- Joint for front_laser -->
  <joint name="joint_front_laser" type="fixed">
    <parent link="base_link"/>
    <child link="front_laser"/>
    <origin xyz="0.25 0.0 0.12" rpy="0.0 0.0 0.0"/>
    <axis xyz="1.0 0.0 1.0"/>
    <limit lower="0.0" upper="0.0" effort="0.0" velocity="0.0"/>
  </joint>

  <!-- Gazebo PlugIns-->
  <gazebo>
     <plugin name="differential_drive_controller" filename="libgazebo_ros_diff_drive.so">
       <rosDebugLevel>Debug</rosDebugLevel>
         <publishWheelTF>True</publishWheelTF>
         <publishTf>1</publishTf>
         <publishOdomTF>true</publishOdomTF>
         <publishWheelJointState>true</publishWheelJointState>
         <alwaysOn>true</alwaysOn>
         <!-- Plugin update rate in Hz -->
        <updateRate>10</updateRate>

        <odometrySource> 1 </odometrySource>
        <!-- Name of left joint, defaults to `left_joint` -->
        <leftJoint>joint_left_wheel</leftJoint>

        <!-- Name of right joint, defaults to `right_joint` -->
        <rightJoint>joint_right_wheel</rightJoint>

        <!-- The distance from the center of one wheel to the other, in meters, defaults to 0.34 m -->
        <wheelSeparation>0.25</wheelSeparation>

        <!-- Diameter of the wheels, in meters, defaults to 0.15 m -->
        <wheelDiameter>0.10</wheelDiameter>

        <!-- Wheel acceleration, in rad/s^2, defaults to 0.0 rad/s^2 -->
        <wheelAcceleration>1.0</wheelAcceleration>

        <!-- Maximum torque which the wheels can produce, in Nm, defaults to 5 Nm -->
        <wheelTorque>10</wheelTorque>

        <!-- Topic to receive geometry_msgs/Twist message commands, defaults to `cmd_vel` -->
        <commandTopic>cmd_vel</commandTopic>

        <!-- Topic to publish nav_msgs/Odometry messages, defaults to `odom` -->
        <odometryTopic>/odom</odometryTopic>

        <odometryFrame>odom</odometryFrame>
        <robotBaseFrame>base_link</robotBaseFrame>
    </plugin>
  </gazebo>
  <gazebo reference="front_laser">
    <sensor type="ray" name="front_laser_sensor">
      <pose>0 0 0 0 0 0</pose>
      <visualize>true</visualize>
      <update_rate>20</update_rate>
      <ray>
        <scan>
            <horizontal>
                <samples>720</samples>
                <resolution>1</resolution>
                <min_angle>-1.570796</min_angle>
                <max_angle>1.570796</max_angle>
            </horizontal>
        </scan>
        <range>
            <min>0.20</min>
            <max>10.0</max>
            <resolution>0.01</resolution>
        </range>
        <noise>
            <type>gaussian</type>
            <mean>0.0</mean>
            <stddev>0.01</stddev>
        </noise>
      </ray>
      <plugin name="my_rb1_raser" filename="libgazebo_ros_laser.so">
       <topicName>/scan</topicName>
        <frameName>front_laser</frameName>
      </plugin>
    </sensor>
  </gazebo>
</robot>
