<?xml version="1.0"?>
<robot name="visual">

<material name="blue">
    <color rgba="0 0 0.8 0.5"/>
</material>
<material name="red">
    <color rgba="0.8 0 0 0.5" />
</material>
<material name="black">
    <color rgba="0 0 0 0.5"/>
</material>
<material name="white">
    <color rgba="1 1 1 0.5"/>
</material>
<!-- Basic Link-->
<link name="base_link">
    <visual>
        <geometry>
            <cylinder radius="0.25" length="0.3"/>
        </geometry>
        <material name="blue"/>
    </visual>
</link>
<!--Link for left_wheel-->
<link name="left_wheel">
    <visual>
        <geometry>
            <cylinder radius="0.025" length="0.03"/>
        </geometry>
        <origin rpy="1.57075 0 0" xyz="0 0 0"/>
        <material name="red" />
    </visual>
</link>
<!-- Joint for left_wheel-->
<joint name="joint_left_wheel" type="continuous">
    <parent link="base_link"/>
    <child link="left_wheel"/>
    <origin xyz="0.0 -0.25 -0.15" rpy="0.0 0.0 0.0"/>        
    <axis rpy="0 0 0" xyz="0 1 0" />
    <limit effort="10000" velocity="1000" />
    <joint_properties damping="1.0" friction="1.0" />
</joint>
<!-- Link for right_wheel -->
<link name="right_wheel">
    <visual>
        <geometry>
            <cylinder radius="0.025" length="0.03"/>
        </geometry>
        <origin rpy="1.57075 0 0" xyz="0 0 0"/>
        <material name="red" />
    </visual>
</link>
<!-- Joint for Right_wheel-->
<joint name="joint_right_wheel" type="continuous">
    <parent link="base_link"/>
    <child link="right_wheel"/>
    <origin xyz="0.0 0.25 -0.15" rpy="0.0 0.0 0.0"/>
    <axis rpy="0 0 0" xyz="0 1 0" />
    <limit effort="10000" velocity="1000" />
    <joint_properties damping="1.0" friction="1.0" />    
</joint>
<link name="front_caster">
    <visual>
        <geometry>
            <sphere radius="0.025"/>
        </geometry>
        <material name="black" />
    </visual>
</link>
<joint name="joint_front_caster" type="continuous">
    <parent link="base_link"/>
    <child link="front_caster"/>
    <origin xyz="0.1 0.0 -0.15" rpy="0.0 0.0 0.0"/>
    <axis xyz="1.0 1.0 0.0"/>
    <limit lower="0.0" upper="0.0" effort="0.0" velocity="0.0"/>    
</joint>
<link name="back_caster">
    <visual>
        <geometry>
            <sphere radius="0.025"/>
        </geometry>
        <material name="black" />
    </visual>
</link>
<joint name="joint_back_caster" type="continuous">
    <parent link="base_link"/>
    <child link="back_caster"/>
    <origin xyz="-0.1 0.0 -0.15" rpy="0.0 0.0 0.0"/>
    <axis xyz="1.0 1.0 0.0"/>
    <limit lower="0.0" upper="0.0" effort="0.0" velocity="0.0"/>
</joint>
<link name="front_laser">
    <visual>
        <geometry>
            <sphere radius="0.02"/>
        </geometry>
        <material name="black"/>
    </visual>
</link>
<joint name="joint_front_laser" type="continuous">
    <parent link="base_link"/>
    <child link="front_laser"/>
    <origin xyz="0.25 0.0 0.12" rpy="0.0 0.0 0.0"/>
    <axis xyz="1.0 0.0 1.0"/>
    <limit lower="0.0" upper="0.0" effort="0.0" velocity="0.0"/>    
</joint>
</robot>
