<?xml version="1.0"?>
<robot name="my_rb1_robot">
  <material name="blue">
    <color rgba="0 0 0.8 1.0"/>
  </material>
  <material name="red">
    <color rgba="0.8 0 0 1.0" />
  </material>
  <material name="black">
    <color rgba="0 0 0 1.0"/>
  </material>
  <material name="white">
    <color rgba="1 1 1 1.0"/>
  </material>

  <!-- Basic Link-->
  <link name="base_link">
    <visual>
      <geometry>
        <cylinder radius="0.25" length="0.3"/>
      </geometry>
      <material name="blue"/>
    </visual>
    <collision>
      <geometry>
        <cylinder radius="0.25" length="0.3"/>
      </geometry>
    </collision>
    <inertial>
      <mass value="1.0"/>
      <inertia ixx="1.0" ixy="0.0" ixz="0.0" iyy="1.0" iyz="0.0" izz="1.0"/>      
    </inertial>
  </link>

  <!--Link for left_wheel-->
  <link name="left_wheel">
    <visual>
      <geometry>
        <cylinder radius="0.025" length="0.03"/>
      </geometry>
      <origin rpy="1.57075 0 0" xyz="0 0 0"/>
      <material name="red" />
    </visual>
    <collision>
      <geometry>
        <cylinder radius="0.025" length="0.03"/>
      </geometry>
    </collision>
    <inertial>
      <mass value="0.1"/>
      <inertia ixx="0.001" ixy="0.0" ixz="0.0" iyy="0.001" iyz="0.0" izz="0.001"/>
    </inertial>
  </link>

  <!-- Joint for left_wheel-->
  <joint name="joint_left_wheel" type="continuous">
    <parent link="base_link"/>
    <child link="left_wheel"/>
    <origin xyz="0.0 -0.25 -0.15" rpy="0.0 0.0 0.0"/>
    <axis rpy="0 0 0" xyz="0 1 0" />
    <limit effort="10000" velocity="1000" />
    <joint_properties damping="1.0" friction="1.0" />
  </joint>

  <!-- Link for right_wheel -->
  <link name="right_wheel">
    <visual>
      <geometry>
        <cylinder radius="0.025" length="0.03"/>
      </geometry>
      <origin rpy="1.57075 0 0" xyz="0 0 0"/>
      <material name="red" />
    </visual>
    <collision>
      <geometry>
        <cylinder radius="0.025" length="0.03"/>
      </geometry>
    </collision>
    <inertial>
      <mass value="0.1"/>
      <inertia ixx="0.001" ixy="0.0" ixz="0.0" iyy="0.001" iyz="0.0" izz="0.001"/>
    </inertial>
  </link>

  <!-- Joint for Right_wheel-->
  <joint name="joint_right_wheel" type="continuous">
    <parent link="base_link"/>
    <child link="right_wheel"/>
    <origin xyz="0.0 0.25 -0.15" rpy="0.0 0.0 0.0"/>
    <axis rpy="0 0 0" xyz="0 1 0" />
    <limit effort="10000" velocity="1000" />
    <joint_properties damping="1.0" friction="1.0" />
  </joint>

  <link name="front_caster">
    <visual>
      <geometry>
        <sphere radius="0.025"/>
      </geometry>
      <material name="black" />
    </visual>
    <collision>
      <geometry>
        <sphere radius="0.025"/>
      </geometry>
    </collision>
    <inertial>
      <mass value="0.01"/>
      <inertia ixx="0.0001" ixy="0.0" ixz="0.0" iyy="0.0001" iyz="0.0" izz="0.0001"/>
    </inertial>
  </link>

  <joint name="joint_front_caster" type="continuous">
    <parent link="base_link"/>
    <child link="front_caster"/>
    <origin xyz="0.1 0.0 -0.15" rpy="0.0 0.0 0.0"/>
    <axis xyz="1.0 1.0 0.0"/>
    <limit lower="0.0" upper="0.0" effort="0.0" velocity="0.0"/>
  </joint>

  <link name="back_caster">
    <visual>
      <geometry>
        <sphere radius="0.025"/>
      </geometry>
      <material name="black" />
    </visual>
    <collision>
      <geometry>
        <sphere radius="0.025"/>
      </geometry>
    </collision>
    <inertial>
      <mass value="0.01"/>
      <inertia ixx="0.0001" ixy="0.0" ixz="0.0" iyy="0.0001" iyz="0.0" izz="0.0001"/>
    </inertial>
  </link>

  <joint name="joint_back_caster" type="continuous">
    <parent link="base_link"/>
    <child link="back_caster"/>
    <origin xyz="-0.1 0.0 -0.15" rpy="0.0 0.0 0.0"/>
    <axis xyz="1.0 1.0 0.0"/>
    <limit lower="0.0" upper="0.0" effort="0.0" velocity="0.0"/>
  </joint>

  <link name="front_laser">
    <visual>
      <geometry>
        <sphere radius="0.02"/>
      </geometry>
      <material name="black"/>
    </visual>
    <collision>
      <geometry>
        <sphere radius="0.02"/>
      </geometry>
    </collision>
    <inertial>
      <mass value="0.01"/>
      <inertia ixx="0.00001" ixy="0.0" ixz="0.0" iyy="0.00001" iyz="0.0" izz="0.00001"/>
    </inertial>
  </link>
  <joint name="joint_front_laser" type="continuous">
    <parent link="base_link"/>
    <child link="front_laser"/>
    <origin xyz="0.25 0.0 0.12" rpy="0.0 0.0 0.0"/>
    <axis xyz="1.0 0.0 1.0"/>
    <limit lower="0.0" upper="0.0" effort="0.0" velocity="0.0"/>
  </joint>
  <gazebo>
     <plugin name="differential_drive_controller" filename="libgazebo_ros_diff_drive.so">
       <rosDebugLevel>Debug</rosDebugLevel>
         <publishWheelTF>True</publishWheelTF>
         <publishTf>1</publishTf>
         <publishWheelJointState>true</publishWheelJointState>
         <alwaysOn>true</alwaysOn>
         <!-- Plugin update rate in Hz -->
        <updateRate>100</updateRate>
    
        <!-- Name of left joint, defaults to `left_joint` -->
        <leftJoint>joint_left_wheel</leftJoint>
    
        <!-- Name of right joint, defaults to `right_joint` -->
        <rightJoint>joint_right_wheel</rightJoint>
    
        <!-- The distance from the center of one wheel to the other, in meters, defaults to 0.34 m -->
        <wheelSeparation>0.25</wheelSeparation>
    
        <!-- Diameter of the wheels, in meters, defaults to 0.15 m -->
        <wheelDiameter>0.05</wheelDiameter>
    
        <!-- Wheel acceleration, in rad/s^2, defaults to 0.0 rad/s^2 -->
        <wheelAcceleration>1.0</wheelAcceleration>
    
        <!-- Maximum torque which the wheels can produce, in Nm, defaults to 5 Nm -->
        <wheelTorque>20</wheelTorque>
    
        <!-- Topic to receive geometry_msgs/Twist message commands, defaults to `cmd_vel` -->
        <commandTopic>cmd_vel</commandTopic>
    
        <!-- Topic to publish nav_msgs/Odometry messages, defaults to `odom` -->
        <odometryTopic>/odom</odometryTopic>
        <robotBaseFrame>base_link</robotBaseFrame>
    </plugin>
  </gazebo>
  <gazebo reference="front_laser">
    <sensor type="ray" name="front_laser_sensor">
      <plugin name="my_rb1_raser" filename="libgazebo_ros_laser.so">
       <topicName>/scan</topicName>
        <frameName>front_laser</frameName>
      </plugin>
    </sensor>
  </gazebo> 
</robot>
